Workbook

Sheet ETFs
A1: Sector | B1: Ticker | C1: ETF Name
A2: Technology | B2: XLK | C2: Technology Select Sector SPDR Fund
A3: Technology | B3: VGT | C3: Vanguard Information Technology ETF
A4: Technology | B4: IYW | C4: iShares U.S. Technology ETF
A5: Technology | B5: SOXX | C5: iShares Semiconductor ETF
A6: Technology | B6: HACK | C6: ETFMG Prime Cyber Security ETF
A7: Technology | B7: BOTZ | C7: Global X Robotics & Artificial Intelligence ETF
A8: Technology | B8: QQQJ | C8: Invesco NASDAQ Next Gen 100 ETF
A9: Healthcare | B9: XLV | C9: Health Care Select Sector SPDR Fund
A10: Healthcare | B10: VHT | C10: Vanguard Health Care ETF
A11: Healthcare | B11: IBB | C11: iShares Nasdaq Biotechnology ETF
A12: Healthcare | B12: XBI | C12: SPDR S&P Biotech ETF
... A33: Crypto | B33: BKCH | C33: Global X Blockchain ETF

Sheet ETF price
B1: XLK | C1: VGT | D1: IYW | E1: SOXX | F1: HACK | G1: BOTZ | H1: QQQJ | I1: XLV | J1: VHT | K1: IBB | L1: XBI | M1: PBE | N1: FHLC | O1: GNOM | P1: XLE | Q1: VDE | R1: XLB | S1: XME | T1: DBC | U1: USO | V1: TAN | W1: XLF | X1: VFH | Y1: KBE | Z1: IYF | AA1: XLRE | AB1: KRE | AC1: IYG | AD1: BTF | AE1: BITO | AF1: CRYP | AG1: BKCH
A2: =IFERROR(__xludf.DUMMYFUNCTION("INDEX(GOOGLEFINANCE(B1,""close"",DATE(2022,1,1),DATE(2024,12,31),""DAILY""),,1)"),"Date") -> Date | B2: =IFERROR(__xludf.DUMMYFUNCTION("INDEX(GOOGLEFINANCE(B1,""close"",DATE(2022,1,1),DATE(2024,12,31),""DAILY""),,2)"),"Close") -> Close | C2: =IFERROR(__xludf.DUMMYFUNCTION("INDEX(GOOGLEFINANCE(C1,""close"",DATE(2022,1,1),DATE(2024,12,31),""DAILY""),,2)"),"Close") -> Close | D2: =IFERROR(__xludf.DUMMYFUNCTION("INDEX(GOOGLEFINANCE(D1,""close"",DATE(2022,1,1),DATE(2024,12,31),""DAILY""),,2)"),"Close") -> Close | E2: =IFERROR(__xludf.DUMMYFUNCTION("INDEX(GOOGLEFINANCE(E1,""close"",DATE(2022,1,1),DATE(2024,12,31),""DAILY""),,2)"),"Close") -> Close | F2: =IFERROR(__xludf.DUMMYFUNCTION("INDEX(GOOGLEFINANCE(F1,""close"",DATE(2022,1,1),DATE(2024,12,31),""DAILY""),,2)"),"Close") -> Close | G2: =IFERROR(__xludf.DUMMYFUNCTION("INDEX(GOOGLEFINANCE(G1,""close"",DATE(2022,1,1),DATE(2024,12,31),""DAILY""),,2)"),"Close") -> Close | H2: =IFERROR(__xludf.DUMMYFUNCTION("INDEX(GOOGLEFINANCE(H1,""close"",DATE(2022,1,1),DATE(2024,12,31),""DAILY""),,2)"),"Close") -> Close | I2: =IFERROR(__xludf.DUMMYFUNCTION("INDEX(GOOGLEFINANCE(I1,""close"",DATE(2022,1,1),DATE(2024,12,31),""DAILY""),,2)"),"Close") -> Close | J2: =IFERROR(__xludf.DUMMYFUNCTION("INDEX(GOOGLEFINANCE(J1,""close"",DATE(2022,1,1),DATE(2024,12,31),""DAILY""),,2)"),"Close") -> Close | K2: =IFERROR(__xludf.DUMMYFUNCTION("INDEX(GOOGLEFINANCE(K1,""close"",DATE(2022,1,1),DATE(2024,12,31),""DAILY""),,2)"),"Close") -> Close | L2: =IFERROR(__xludf.DUMMYFUNCTION("INDEX(GOOGLEFINANCE(L1,""close"",DATE(2022,1,1),DATE(2024,12,31),""DAILY""),,2)"),"Close") -> Close | M2: =IFERROR(__xludf.DUMMYFUNCTION("INDEX(GOOGLEFINANCE(M1,""close"",DATE(2022,1,1),DATE(2024,12,31),""DAILY""),,2)"),"Close") -> Close | N2: =IFERROR(__xludf.DUMMYFUNCTION("INDEX(GOOGLEFINANCE(N1,""close"",DATE(2022,1,1),DATE(2024,12,31),""DAILY""),,2)"),"Close") -> Close | O2: =IFERROR(__xludf.DUMMYFUNCTION("INDEX(GOOGLEFINANCE(O1,""close"",DATE(2022,1,1),DATE(2024,12,31),""DAILY""),,2)"),"Close") -> Close | P2: =IFERROR(__xludf.DUMMYFUNCTION("INDEX(GOOGLEFINANCE(P1,""close"",DATE(2022,1,1),DATE(2024,12,31),""DAILY""),,2)"),"Close") -> Close | Q2: =IFERROR(__xludf.DUMMYFUNCTION("INDEX(GOOGLEFINANCE(Q1,""close"",DATE(2022,1,1),DATE(2024,12,31),""DAILY""),,2)"),"Close") -> Close | R2: =IFERROR(__xludf.DUMMYFUNCTION("INDEX(GOOGLEFINANCE(R1,""close"",DATE(2022,1,1),DATE(2024,12,31),""DAILY""),,2)"),"Close") -> Close | S2: =IFERROR(__xludf.DUMMYFUNCTION("INDEX(GOOGLEFINANCE(S1,""close"",DATE(2022,1,1),DATE(2024,12,31),""DAILY""),,2)"),"Close") -> Close | T2: =IFERROR(__xludf.DUMMYFUNCTION("INDEX(GOOGLEFINANCE(T1,""close"",DATE(2022,1,1),DATE(2024,12,31),""DAILY""),,2)"),"Close") -> Close | U2: =IFERROR(__xludf.DUMMYFUNCTION("INDEX(GOOGLEFINANCE(U1,""close"",DATE(2022,1,1),DATE(2024,12,31),""DAILY""),,2)"),"Close") -> Close | V2: =IFERROR(__xludf.DUMMYFUNCTION("INDEX(GOOGLEFINANCE(V1,""close"",DATE(2022,1,1),DATE(2024,12,31),""DAILY""),,2)"),"Close") -> Close | W2: =IFERROR(__xludf.DUMMYFUNCTION("INDEX(GOOGLEFINANCE(W1,""close"",DATE(2022,1,1),DATE(2024,12,31),""DAILY""),,2)"),"Close") -> Close | X2: =IFERROR(__xludf.DUMMYFUNCTION("INDEX(GOOGLEFINANCE(X1,""close"",DATE(2022,1,1),DATE(2024,12,31),""DAILY""),,2)"),"Close") -> Close | Y2: =IFERROR(__xludf.DUMMYFUNCTION("INDEX(GOOGLEFINANCE(Y1,""close"",DATE(2022,1,1),DATE(2024,12,31),""DAILY""),,2)"),"Close") -> Close | Z2: =IFERROR(__xludf.DUMMYFUNCTION("INDEX(GOOGLEFINANCE(Z1,""close"",DATE(2022,1,1),DATE(2024,12,31),""DAILY""),,2)"),"Close") -> Close | AA2: =IFERROR(__xludf.DUMMYFUNCTION("INDEX(GOOGLEFINANCE(AA1,""close"",DATE(2022,1,1),DATE(2024,12,31),""DAILY""),,2)"),"Close") -> Close | AB2: =IFERROR(__xludf.DUMMYFUNCTION("INDEX(GOOGLEFINANCE(AB1,""close"",DATE(2022,1,1),DATE(2024,12,31),""DAILY""),,2)"),"Close") -> Close | AC2: =IFERROR(__xludf.DUMMYFUNCTION("INDEX(GOOGLEFINANCE(AC1,""close"",DATE(2022,1,1),DATE(2024,12,31),""DAILY""),,2)"),"Close") -> Close | AD2: =IFERROR(__xludf.DUMMYFUNCTION("INDEX(GOOGLEFINANCE(AD1,""close"",DATE(2022,1,1),DATE(2024,12,31),""DAILY""),,2)"),"Close") -> Close | AE2: =IFERROR(__xludf.DUMMYFUNCTION("INDEX(GOOGLEFINANCE(AE1,""close"",DATE(2022,1,1),DATE(2024,12,31),""DAILY""),,2)"),"Close") -> Close | AF2: =IFERROR(__xludf.DUMMYFUNCTION("INDEX(GOOGLEFINANCE(AF1,""close"",DATE(2022,1,1),DATE(2024,12,31),""DAILY""),,2)"),"Close") -> Close | AG2: =IFERROR(__xludf.DUMMYFUNCTION("INDEX(GOOGLEFINANCE(AG1,""close"",DATE(2022,1,1),DATE(2024,12,31),""DAILY""),,2)"),"Close") -> Close
A3: =IFERROR(__xludf.DUMMYFUNCTION("""COMPUTED_VALUE"""),44564.6666666666) -> 44564.667 | B3: =IFERROR(__xludf.DUMMYFUNCTION("""COMPUTED_VALUE"""),175.52) -> 175.52 | C3: =IFERROR(__xludf.DUMMYFUNCTION("""COMPUTED_VALUE"""),462) -> 462 | D3: =IFERROR(__xludf.DUMMYFUNCTION("""COMPUTED_VALUE"""),115.41) -> 115.41 | E3: =IFERROR(__xludf.DUMMYFUNCTION("""COMPUTED_VALUE"""),184.37) -> 184.37 | F3: =IFERROR(__xludf.DUMMYFUNCTION("""COMPUTED_VALUE"""),61.26) -> 61.26 | G3: =IFERROR(__xludf.DUMMYFUNCTION("""COMPUTED_VALUE"""),36.09) -> 36.09 | H3: =IFERROR(__xludf.DUMMYFUNCTION("""COMPUTED_VALUE"""),33.45) -> 33.45 | I3: =IFERROR(__xludf.DUMMYFUNCTION("""COMPUTED_VALUE"""),139.44) -> 139.44 | J3: =IFERROR(__xludf.DUMMYFUNCTION("""COMPUTED_VALUE"""),264.71) -> 264.71 | K3: =IFERROR(__xludf.DUMMYFUNCTION("""COMPUTED_VALUE"""),152.37) -> 152.37 | L3: =IFERROR(__xludf.DUMMYFUNCTION("""COMPUTED_VALUE"""),115.44) -> 115.44 | M3: =IFERROR(__xludf.DUMMYFUNCTION("""COMPUTED_VALUE"""),71.43) -> 71.43 | N3: =IFERROR(__xludf.DUMMYFUNCTION("""COMPUTED_VALUE"""),68.16) -> 68.16 | O3: =IFERROR(__xludf.DUMMYFUNCTION("""COMPUTED_VALUE"""),79.92) -> 79.92 | P3: =IFERROR(__xludf.DUMMYFUNCTION("""COMPUTED_VALUE"""),57.22) -> 57.22 | Q3: =IFERROR(__xludf.DUMMYFUNCTION("""COMPUTED_VALUE"""),80.1) -> 80.1 | R3: =IFERROR(__xludf.DUMMYFUNCTION("""COMPUTED_VALUE"""),89.43) -> 89.43 | S3: =IFERROR(__xludf.DUMMYFUNCTION("""COMPUTED_VALUE"""),45.54) -> 45.54 | T3: =IFERROR(__xludf.DUMMYFUNCTION("""COMPUTED_VALUE"""),20.86) -> 20.86 | U3: =IFERROR(__xludf.DUMMYFUNCTION("""COMPUTED_VALUE"""),54.83) -> 54.83 | V3: =IFERROR(__xludf.DUMMYFUNCTION("""COMPUTED_VALUE"""),78.49) -> 78.49 | W3: =IFERROR(__xludf.DUMMYFUNCTION("""COMPUTED_VALUE"""),39.53) -> 39.53 | X3: =IFERROR(__xludf.DUMMYFUNCTION("""COMPUTED_VALUE"""),97.67) -> 97.67 | Y3: =IFERROR(__xludf.DUMMYFUNCTION("""COMPUTED_VALUE"""),55.64) -> 55.64 | Z3: =IFERROR(__xludf.DUMMYFUNCTION("""COMPUTED_VALUE"""),87.57) -> 87.57 | AA3: =IFERROR(__xludf.DUMMYFUNCTION("""COMPUTED_VALUE"""),51.33) -> 51.33 | AB3: =IFERROR(__xludf.DUMMYFUNCTION("""COMPUTED_VALUE"""),72.17) -> 72.17 | AC3: =IFERROR(__xludf.DUMMYFUNCTION("""COMPUTED_VALUE"""),65.45) -> 65.45 | AD3: =IFERROR(__xludf.DUMMYFUNCTION("""COMPUTED_VALUE"""),17.9) -> 17.9 | AE3: =IFERROR(__xludf.DUMMYFUNCTION("""COMPUTED_VALUE"""),28.95) -> 28.95 | AF3: =IFERROR(__xludf.DUMMYFUNCTION("""COMPUTED_VALUE"""),7.81) -> 7.81 | AG3: =IFERROR(__xludf.DUMMYFUNCTION("""COMPUTED_VALUE"""),88.52) -> 88.52
A4: =IFERROR(__xludf.DUMMYFUNCTION("""COMPUTED_VALUE"""),44565.6666666666) -> 44565.667 | B4: =IFERROR(__xludf.DUMMYFUNCTION("""COMPUTED_VALUE"""),173.66) -> 173.66 | C4: =IFERROR(__xludf.DUMMYFUNCTION("""COMPUTED_VALUE"""),456.16) -> 456.16 | D4: =IFERROR(__xludf.DUMMYFUNCTION("""COMPUTED_VALUE"""),113.91) -> 113.91 | E4: =IFERROR(__xludf.DUMMYFUNCTION("""COMPUTED_VALUE"""),183.8) -> 183.8 | F4: =IFERROR(__xludf.DUMMYFUNCTION("""COMPUTED_VALUE"""),60.03) -> 60.03 | G4: =IFERROR(__xludf.DUMMYFUNCTION("""COMPUTED_VALUE"""),35.87) -> 35.87 | H4: =IFERROR(__xludf.DUMMYFUNCTION("""COMPUTED_VALUE"""),33.04) -> 33.04 | I4: =IFERROR(__xludf.DUMMYFUNCTION("""COMPUTED_VALUE"""),137.6) -> 137.6 | J4: =IFERROR(__xludf.DUMMYFUNCTION("""COMPUTED_VALUE"""),260.46) -> 260.46 | K4: =IFERROR(__xludf.DUMMYFUNCTION("""COMPUTED_VALUE"""),148.29) -> 148.29 | L4: =IFERROR(__xludf.DUMMYFUNCTION("""COMPUTED_VALUE"""),111.36) -> 111.36 | M4: =IFERROR(__xludf.DUMMYFUNCTION("""COMPUTED_VALUE"""),68.74) -> 68.74 | N4: =IFERROR(__xludf.DUMMYFUNCTION("""COMPUTED_VALUE"""),67.15) -> 67.15 | O4: =IFERROR(__xludf.DUMMYFUNCTION("""COMPUTED_VALUE"""),76.52) -> 76.52 | P4: =IFERROR(__xludf.DUMMYFUNCTION("""COMPUTED_VALUE"""),59.2) -> 59.2 | Q4: =IFERROR(__xludf.DUMMYFUNCTION("""COMPUTED_VALUE"""),82.9) -> 82.9 | R4: =IFERROR(__xludf.DUMMYFUNCTION("""COMPUTED_VALUE"""),90.53) -> 90.53 | S4: =IFERROR(__xludf.DUMMYFUNCTION("""COMPUTED_VALUE"""),46.19) -> 46.19 | T4: =IFERROR(__xludf.DUMMYFUNCTION("""COMPUTED_VALUE"""),21.11) -> 21.11 | U4: =IFERROR(__xludf.DUMMYFUNCTION("""COMPUTED_VALUE"""),55.59) -> 55.59 | V4: =IFERROR(__xludf.DUMMYFUNCTION("""COMPUTED_VALUE"""),76.32) -> 76.32 | W4: =IFERROR(__xludf.DUMMYFUNCTION("""COMPUTED_VALUE"""),40.57) -> 40.57 | X4: =IFERROR(__xludf.DUMMYFUNCTION("""COMPUTED_VALUE"""),99.9) -> 99.9 | Y4: =IFERROR(__xludf.DUMMYFUNCTION("""COMPUTED_VALUE"""),57.14) -> 57.14 | Z4: =IFERROR(__xludf.DUMMYFUNCTION("""COMPUTED_VALUE"""),89.6) -> 89.6 | AA4: =IFERROR(__xludf.DUMMYFUNCTION("""COMPUTED_VALUE"""),51.13) -> 51.13 | AB4: =IFERROR(__xludf.DUMMYFUNCTION("""COMPUTED_VALUE"""),74.21) -> 74.21 | AC4: =IFERROR(__xludf.DUMMYFUNCTION("""COMPUTED_VALUE"""),66.85) -> 66.85 | AD4: =IFERROR(__xludf.DUMMYFUNCTION("""COMPUTED_VALUE"""),18.06) -> 18.06 | AE4: =IFERROR(__xludf.DUMMYFUNCTION("""COMPUTED_VALUE"""),29.22) -> 29.22 | AF4: =IFERROR(__xludf.DUMMYFUNCTION("""COMPUTED_VALUE"""),7.66) -> 7.66 | AG4: =IFERROR(__xludf.DUMMYFUNCTION("""COMPUTED_VALUE"""),88.36) -> 88.36
A5: =IFERROR(__xludf.DUMMYFUNCTION("""COMPUTED_VALUE"""),44566.6666666666) -> 44566.667 | B5: =IFERROR(__xludf.DUMMYFUNCTION("""COMPUTED_VALUE"""),168.32) -> 168.32 | C5: =IFERROR(__xludf.DUMMYFUNCTION("""COMPUTED_VALUE"""),441.02) -> 441.02 | D5: =IFERROR(__xludf.DUMMYFUNCTION("""COMPUTED_VALUE"""),109.66) -> 109.66 | E5: =IFERROR(__xludf.DUMMYFUNCTION("""COMPUTED_VALUE"""),177.56) -> 177.56 | F5: =IFERROR(__xludf.DUMMYFUNCTION("""COMPUTED_VALUE"""),58.16) -> 58.16 | G5: =IFERROR(__xludf.DUMMYFUNCTION("""COMPUTED_VALUE"""),34.8) -> 34.8 | H5: =IFERROR(__xludf.DUMMYFUNCTION("""COMPUTED_VALUE"""),31.79) -> 31.79 | I5: =IFERROR(__xludf.DUMMYFUNCTION("""COMPUTED_VALUE"""),136.62) -> 136.62 | J5: =IFERROR(__xludf.DUMMYFUNCTION("""COMPUTED_VALUE"""),257.28) -> 257.28 | K5: =IFERROR(__xludf.DUMMYFUNCTION("""COMPUTED_VALUE"""),142.5) -> 142.5 | L5: =IFERROR(__xludf.DUMMYFUNCTION("""COMPUTED_VALUE"""),105.23) -> 105.23 | M5: =IFERROR(__xludf.DUMMYFUNCTION("""COMPUTED_VALUE"""),65.84) -> 65.84 | N5: =IFERROR(__xludf.DUMMYFUNCTION("""COMPUTED_VALUE"""),66.29) -> 66.29 | O5: =IFERROR(__xludf.DUMMYFUNCTION("""COMPUTED_VALUE"""),72.48) -> 72.48 | P5: =IFERROR(__xludf.DUMMYFUNCTION("""COMPUTED_VALUE"""),59.19) -> 59.19 | Q5: =IFERROR(__xludf.DUMMYFUNCTION("""COMPUTED_VALUE"""),82.53) -> 82.53 | R5: =IFERROR(__xludf.DUMMYFUNCTION("""COMPUTED_VALUE"""),90.52) -> 90.52 | S5: =IFERROR(__xludf.DUMMYFUNCTION("""COMPUTED_VALUE"""),46.25) -> 46.25 | T5: =IFERROR(__xludf.DUMMYFUNCTION("""COMPUTED_VALUE"""),21.02) -> 21.02 | U5: =IFERROR(__xludf.DUMMYFUNCTION("""COMPUTED_VALUE"""),55.43) -> 55.43 | V5: =IFERROR(__xludf.DUMMYFUNCTION("""COMPUTED_VALUE"""),71.21) -> 71.21 | W5: =IFERROR(__xludf.DUMMYFUNCTION("""COMPUTED_VALUE"""),40.1) -> 40.1 | X5: =IFERROR(__xludf.DUMMYFUNCTION("""COMPUTED_VALUE"""),98.48) -> 98.48 | Y5: =IFERROR(__xludf.DUMMYFUNCTION("""COMPUTED_VALUE"""),56.71) -> 56.71 | Z5: =IFERROR(__xludf.DUMMYFUNCTION("""COMPUTED_VALUE"""),88.38) -> 88.38 | AA5: =IFERROR(__xludf.DUMMYFUNCTION("""COMPUTED_VALUE"""),49.47) -> 49.47 | AB5: =IFERROR(__xludf.DUMMYFUNCTION("""COMPUTED_VALUE"""),73.73) -> 73.73 | AC5: =IFERROR(__xludf.DUMMYFUNCTION("""COMPUTED_VALUE"""),65.91) -> 65.91 | AD5: =IFERROR(__xludf.DUMMYFUNCTION("""COMPUTED_VALUE"""),17.07) -> 17.07 | AE5: =IFERROR(__xludf.DUMMYFUNCTION("""COMPUTED_VALUE"""),27.64) -> 27.64 | AF5: =IFERROR(__xludf.DUMMYFUNCTION("""COMPUTED_VALUE"""),7.01) -> 7.01 | AG5: =IFERROR(__xludf.DUMMYFUNCTION("""COMPUTED_VALUE"""),81.22) -> 81.22
A6: =IFERROR(__xludf.DUMMYFUNCTION("""COMPUTED_VALUE"""),44567.6666666666) -> 44567.667 | B6: =IFERROR(__xludf.DUMMYFUNCTION("""COMPUTED_VALUE"""),167.47) -> 167.47 | C6: =IFERROR(__xludf.DUMMYFUNCTION("""COMPUTED_VALUE"""),439.35) -> 439.35 | D6: =IFERROR(__xludf.DUMMYFUNCTION("""COMPUTED_VALUE"""),109.53) -> 109.53 | E6: =IFERROR(__xludf.DUMMYFUNCTION("""COMPUTED_VALUE"""),178.94) -> 178.94 | F6: =IFERROR(__xludf.DUMMYFUNCTION("""COMPUTED_VALUE"""),58.18) -> 58.18 | G6: =IFERROR(__xludf.DUMMYFUNCTION("""COMPUTED_VALUE"""),34.47) -> 34.47 | H6: =IFERROR(__xludf.DUMMYFUNCTION("""COMPUTED_VALUE"""),31.8) -> 31.8 | I6: =IFERROR(__xludf.DUMMYFUNCTION("""COMPUTED_VALUE"""),135.04) -> 135.04 | J6: =IFERROR(__xludf.DUMMYFUNCTION("""COMPUTED_VALUE"""),254.04) -> 254.04 | K6: =IFERROR(__xludf.DUMMYFUNCTION("""COMPUTED_VALUE"""),142.42) -> 142.42 | L6: =IFERROR(__xludf.DUMMYFUNCTION("""COMPUTED_VALUE"""),105.2) -> 105.2 | M6: =IFERROR(__xludf.DUMMYFUNCTION("""COMPUTED_VALUE"""),66.08) -> 66.08 | N6: =IFERROR(__xludf.DUMMYFUNCTION("""COMPUTED_VALUE"""),65.56) -> 65.56 | O6: =IFERROR(__xludf.DUMMYFUNCTION("""COMPUTED_VALUE"""),72.44) -> 72.44 | P6: =IFERROR(__xludf.DUMMYFUNCTION("""COMPUTED_VALUE"""),60.51) -> 60.51 | Q6: =IFERROR(__xludf.DUMMYFUNCTION("""COMPUTED_VALUE"""),84.48) -> 84.48 | R6: =IFERROR(__xludf.DUMMYFUNCTION("""COMPUTED_VALUE"""),89.38) -> 89.38 | S6: =IFERROR(__xludf.DUMMYFUNCTION("""COMPUTED_VALUE"""),45.57) -> 45.57 | T6: =IFERROR(__xludf.DUMMYFUNCTION("""COMPUTED_VALUE"""),21.2) -> 21.2 | U6: =IFERROR(__xludf.DUMMYFUNCTION("""COMPUTED_VALUE"""),56.89) -> 56.89 | V6: =IFERROR(__xludf.DUMMYFUNCTION("""COMPUTED_VALUE"""),70.63) -> 70.63 | W6: =IFERROR(__xludf.DUMMYFUNCTION("""COMPUTED_VALUE"""),40.69) -> 40.69 | X6: =IFERROR(__xludf.DUMMYFUNCTION("""COMPUTED_VALUE"""),100.1) -> 100.1 | Y6: =IFERROR(__xludf.DUMMYFUNCTION("""COMPUTED_VALUE"""),58.64) -> 58.64 | Z6: =IFERROR(__xludf.DUMMYFUNCTION("""COMPUTED_VALUE"""),89.79) -> 89.79 | AA6: =IFERROR(__xludf.DUMMYFUNCTION("""COMPUTED_VALUE"""),49.53) -> 49.53 | AB6: =IFERROR(__xludf.DUMMYFUNCTION("""COMPUTED_VALUE"""),76.52) -> 76.52 | AC6: =IFERROR(__xludf.DUMMYFUNCTION("""COMPUTED_VALUE"""),66.76) -> 66.76 | AD6: =IFERROR(__xludf.DUMMYFUNCTION("""COMPUTED_VALUE"""),16.86) -> 16.86 | AE6: =IFERROR(__xludf.DUMMYFUNCTION("""COMPUTED_VALUE"""),27.28) -> 27.28 | AF6: =IFERROR(__xludf.DUMMYFUNCTION("""COMPUTED_VALUE"""),6.91) -> 6.91 | AG6: =IFERROR(__xludf.DUMMYFUNCTION("""COMPUTED_VALUE"""),79.72) -> 79.72
A7: =IFERROR(__xludf.DUMMYFUNCTION("""COMPUTED_VALUE"""),44568.6666666666) -> 44568.667 | B7: =IFERROR(__xludf.DUMMYFUNCTION("""COMPUTED_VALUE"""),165.93) -> 165.93 | C7: =IFERROR(__xludf.DUMMYFUNCTION("""COMPUTED_VALUE"""),434.86) -> 434.86 | D7: =IFERROR(__xludf.DUMMYFUNCTION("""COMPUTED_VALUE"""),108.42) -> 108.42 | E7: =IFERROR(__xludf.DUMMYFUNCTION("""COMPUTED_VALUE"""),173.75) -> 173.75 | F7: =IFERROR(__xludf.DUMMYFUNCTION("""COMPUTED_VALUE"""),57.94) -> 57.94 | G7: =IFERROR(__xludf.DUMMYFUNCTION("""COMPUTED_VALUE"""),33.9) -> 33.9 | H7: =IFERROR(__xludf.DUMMYFUNCTION("""COMPUTED_VALUE"""),31.52) -> 31.52 | I7: =IFERROR(__xludf.DUMMYFUNCTION("""COMPUTED_VALUE"""),134.35) -> 134.35 | J7: =IFERROR(__xludf.DUMMYFUNCTION("""COMPUTED_VALUE"""),252.48) -> 252.48 | K7: =IFERROR(__xludf.DUMMYFUNCTION("""COMPUTED_VALUE"""),140.55) -> 140.55 | L7: =IFERROR(__xludf.DUMMYFUNCTION("""COMPUTED_VALUE"""),102.99) -> 102.99 | M7: =IFERROR(__xludf.DUMMYFUNCTION("""COMPUTED_VALUE"""),65.28) -> 65.28 | N7: =IFERROR(__xludf.DUMMYFUNCTION("""COMPUTED_VALUE"""),65.06) -> 65.06 | O7: =IFERROR(__xludf.DUMMYFUNCTION("""COMPUTED_VALUE"""),71.24) -> 71.24 | P7: =IFERROR(__xludf.DUMMYFUNCTION("""COMPUTED_VALUE"""),61.34) -> 61.34 | Q7: =IFERROR(__xludf.DUMMYFUNCTION("""COMPUTED_VALUE"""),85.52) -> 85.52 | R7: =IFERROR(__xludf.DUMMYFUNCTION("""COMPUTED_VALUE"""),89.3) -> 89.3 | S7: =IFERROR(__xludf.DUMMYFUNCTION("""COMPUTED_VALUE"""),46.07) -> 46.07 | T7: =IFERROR(__xludf.DUMMYFUNCTION("""COMPUTED_VALUE"""),21.24) -> 21.24 | U7: =IFERROR(__xludf.DUMMYFUNCTION("""COMPUTED_VALUE"""),56.67) -> 56.67 | V7: =IFERROR(__xludf.DUMMYFUNCTION("""COMPUTED_VALUE"""),70.75) -> 70.75 | W7: =IFERROR(__xludf.DUMMYFUNCTION("""COMPUTED_VALUE"""),41.17) -> 41.17 | X7: =IFERROR(__xludf.DUMMYFUNCTION("""COMPUTED_VALUE"""),101.06) -> 101.06 | Y7: =IFERROR(__xludf.DUMMYFUNCTION("""COMPUTED_VALUE"""),59.28) -> 59.28 | Z7: =IFERROR(__xludf.DUMMYFUNCTION("""COMPUTED_VALUE"""),90.64) -> 90.64 | AA7: =IFERROR(__xludf.DUMMYFUNCTION("""COMPUTED_VALUE"""),49.27) -> 49.27 | AB7: =IFERROR(__xludf.DUMMYFUNCTION("""COMPUTED_VALUE"""),77.27) -> 77.27 | AC7: =IFERROR(__xludf.DUMMYFUNCTION("""COMPUTED_VALUE"""),67.16) -> 67.16 | AD7: =IFERROR(__xludf.DUMMYFUNCTION("""COMPUTED_VALUE"""),16.32) -> 16.32 | AE7: =IFERROR(__xludf.DUMMYFUNCTION("""COMPUTED_VALUE"""),26.41) -> 26.41 | AF7: =IFERROR(__xludf.DUMMYFUNCTION("""COMPUTED_VALUE"""),6.96) -> 6.96 | AG7: =IFERROR(__xludf.DUMMYFUNCTION("""COMPUTED_VALUE"""),78.76) -> 78.76
A8: =IFERROR(__xludf.DUMMYFUNCTION("""COMPUTED_VALUE"""),44571.6666666666) -> 44571.667 | B8: =IFERROR(__xludf.DUMMYFUNCTION("""COMPUTED_VALUE"""),165.96) -> 165.96 | C8: =IFERROR(__xludf.DUMMYFUNCTION("""COMPUTED_VALUE"""),435.32) -> 435.32 | D8: =IFERROR(__xludf.DUMMYFUNCTION("""COMPUTED_VALUE"""),108.83) -> 108.83 | E8: =IFERROR(__xludf.DUMMYFUNCTION("""COMPUTED_VALUE"""),173.81) -> 173.81 | F8: =IFERROR(__xludf.DUMMYFUNCTION("""COMPUTED_VALUE"""),58.39) -> 58.39 | G8: =IFERROR(__xludf.DUMMYFUNCTION("""COMPUTED_VALUE"""),33.43) -> 33.43 | H8: =IFERROR(__xludf.DUMMYFUNCTION("""COMPUTED_VALUE"""),31.58) -> 31.58 | I8: =IFERROR(__xludf.DUMMYFUNCTION("""COMPUTED_VALUE"""),135.73) -> 135.73 | J8: =IFERROR(__xludf.DUMMYFUNCTION("""COMPUTED_VALUE"""),255.19) -> 255.19 | K8: =IFERROR(__xludf.DUMMYFUNCTION("""COMPUTED_VALUE"""),142.16) -> 142.16 | L8: =IFERROR(__xludf.DUMMYFUNCTION("""COMPUTED_VALUE"""),103.14) -> 103.14 | M8: =IFERROR(__xludf.DUMMYFUNCTION("""COMPUTED_VALUE"""),66) -> 66 | N8: =IFERROR(__xludf.DUMMYFUNCTION("""COMPUTED_VALUE"""),65.69) -> 65.69 | O8: =IFERROR(__xludf.DUMMYFUNCTION("""COMPUTED_VALUE"""),71.48) -> 71.48 | P8: =IFERROR(__xludf.DUMMYFUNCTION("""COMPUTED_VALUE"""),61.15) -> 61.15 | Q8: =IFERROR(__xludf.DUMMYFUNCTION("""COMPUTED_VALUE"""),85.24) -> 85.24 | R8: =IFERROR(__xludf.DUMMYFUNCTION("""COMPUTED_VALUE"""),88.39) -> 88.39 | S8: =IFERROR(__xludf.DUMMYFUNCTION("""COMPUTED_VALUE"""),45.69) -> 45.69 | T8: =IFERROR(__xludf.DUMMYFUNCTION("""COMPUTED_VALUE"""),21.15) -> 21.15 | U8: =IFERROR(__xludf.DUMMYFUNCTION("""COMPUTED_VALUE"""),56.16) -> 56.16 | V8: =IFERROR(__xludf.DUMMYFUNCTION("""COMPUTED_VALUE"""),70.7) -> 70.7 | W8: =IFERROR(__xludf.DUMMYFUNCTION("""COMPUTED_VALUE"""),41.03) -> 41.03 | X8: =IFERROR(__xludf.DUMMYFUNCTION("""COMPUTED_VALUE"""),100.77) -> 100.77 | Y8: =IFERROR(__xludf.DUMMYFUNCTION("""COMPUTED_VALUE"""),59.28) -> 59.28 | Z8: =IFERROR(__xludf.DUMMYFUNCTION("""COMPUTED_VALUE"""),90.37) -> 90.37 | AA8: =IFERROR(__xludf.DUMMYFUNCTION("""COMPUTED_VALUE"""),48.98) -> 48.98 | AB8: =IFERROR(__xludf.DUMMYFUNCTION("""COMPUTED_VALUE"""),77.15) -> 77.15 | AC8: =IFERROR(__xludf.DUMMYFUNCTION("""COMPUTED_VALUE"""),66.78) -> 66.78 | AD8: =IFERROR(__xludf.DUMMYFUNCTION("""COMPUTED_VALUE"""),16.25) -> 16.25 | AE8: =IFERROR(__xludf.DUMMYFUNCTION("""COMPUTED_VALUE"""),26.31) -> 26.31 | AF8: =IFERROR(__xludf.DUMMYFUNCTION("""COMPUTED_VALUE"""),6.8) -> 6.8 | AG8: =IFERROR(__xludf.DUMMYFUNCTION("""COMPUTED_VALUE"""),77.36) -> 77.36
A9: =IFERROR(__xludf.DUMMYFUNCTION("""COMPUTED_VALUE"""),44572.6666666666) -> 44572.667 | B9: =IFERROR(__xludf.DUMMYFUNCTION("""COMPUTED_VALUE"""),167.95) -> 167.95 | C9: =IFERROR(__xludf.DUMMYFUNCTION("""COMPUTED_VALUE"""),441.07) -> 441.07 | D9: =IFERROR(__xludf.DUMMYFUNCTION("""COMPUTED_VALUE"""),110.26) -> 110.26 | E9: =IFERROR(__xludf.DUMMYFUNCTION("""COMPUTED_VALUE"""),177.08) -> 177.08 | F9: =IFERROR(__xludf.DUMMYFUNCTION("""COMPUTED_VALUE"""),59.11) -> 59.11 | G9: =IFERROR(__xludf.DUMMYFUNCTION("""COMPUTED_VALUE"""),33.63) -> 33.63 | H9: =IFERROR(__xludf.DUMMYFUNCTION("""COMPUTED_VALUE"""),31.95) -> 31.95 | I9: =IFERROR(__xludf.DUMMYFUNCTION("""COMPUTED_VALUE"""),136.81) -> 136.81 | J9: =IFERROR(__xludf.DUMMYFUNCTION("""COMPUTED_VALUE"""),257.29) -> 257.29 | K9: =IFERROR(__xludf.DUMMYFUNCTION("""COMPUTED_VALUE"""),143.52) -> 143.52 | L9: =IFERROR(__xludf.DUMMYFUNCTION("""COMPUTED_VALUE"""),103.89) -> 103.89 | M9: =IFERROR(__xludf.DUMMYFUNCTION("""COMPUTED_VALUE"""),66.16) -> 66.16 | N9: =IFERROR(__xludf.DUMMYFUNCTION("""COMPUTED_VALUE"""),66.22) -> 66.22 | O9: =IFERROR(__xludf.DUMMYFUNCTION("""COMPUTED_VALUE"""),72) -> 72 | P9: =IFERROR(__xludf.DUMMYFUNCTION("""COMPUTED_VALUE"""),63.23) -> 63.23 | Q9: =IFERROR(__xludf.DUMMYFUNCTION("""COMPUTED_VALUE"""),88.22) -> 88.22 | R9: =IFERROR(__xludf.DUMMYFUNCTION("""COMPUTED_VALUE"""),89.36) -> 89.36 | S9: =IFERROR(__xludf.DUMMYFUNCTION("""COMPUTED_VALUE"""),46.49) -> 46.49 | T9: =IFERROR(__xludf.DUMMYFUNCTION("""COMPUTED_VALUE"""),21.56) -> 21.56 | U9: =IFERROR(__xludf.DUMMYFUNCTION("""COMPUTED_VALUE"""),58.16) -> 58.16 | V9: =IFERROR(__xludf.DUMMYFUNCTION("""COMPUTED_VALUE"""),71.91) -> 71.91 | W9: =IFERROR(__xludf.DUMMYFUNCTION("""COMPUTED_VALUE"""),41.39) -> 41.39 | X9: =IFERROR(__xludf.DUMMYFUNCTION("""COMPUTED_VALUE"""),101.74) -> 101.74 | Y9: =IFERROR(__xludf.DUMMYFUNCTION("""COMPUTED_VALUE"""),59.63) -> 59.63 | Z9: =IFERROR(__xludf.DUMMYFUNCTION("""COMPUTED_VALUE"""),91.28) -> 91.28 | AA9: =IFERROR(__xludf.DUMMYFUNCTION("""COMPUTED_VALUE"""),48.9) -> 48.9 | AB9: =IFERROR(__xludf.DUMMYFUNCTION("""COMPUTED_VALUE"""),77.42) -> 77.42 | AC9: =IFERROR(__xludf.DUMMYFUNCTION("""COMPUTED_VALUE"""),67.56) -> 67.56 | AD9: =IFERROR(__xludf.DUMMYFUNCTION("""COMPUTED_VALUE"""),16.71) -> 16.71 | AE9: =IFERROR(__xludf.DUMMYFUNCTION("""COMPUTED_VALUE"""),27.01) -> 27.01 | AF9: =IFERROR(__xludf.DUMMYFUNCTION("""COMPUTED_VALUE"""),7.07) -> 7.07 | AG9: =IFERROR(__xludf.DUMMYFUNCTION("""COMPUTED_VALUE"""),82.56) -> 82.56
A10: =IFERROR(__xludf.DUMMYFUNCTION("""COMPUTED_VALUE"""),44573.6666666666) -> 44573.667 | B10: =IFERROR(__xludf.DUMMYFUNCTION("""COMPUTED_VALUE"""),168.74) -> 168.74 | C10: =IFERROR(__xludf.DUMMYFUNCTION("""COMPUTED_VALUE"""),442.51) -> 442.51 | D10: =IFERROR(__xludf.DUMMYFUNCTION("""COMPUTED_VALUE"""),110.79) -> 110.79 | E10: =IFERROR(__xludf.DUMMYFUNCTION("""COMPUTED_VALUE"""),178.38) -> 178.38 | F10: =IFERROR(__xludf.DUMMYFUNCTION("""COMPUTED_VALUE"""),58.71) -> 58.71 | G10: =IFERROR(__xludf.DUMMYFUNCTION("""COMPUTED_VALUE"""),33.98) -> 33.98 | H10: =IFERROR(__xludf.DUMMYFUNCTION("""COMPUTED_VALUE"""),31.85) -> 31.85 | I10: =IFERROR(__xludf.DUMMYFUNCTION("""COMPUTED_VALUE"""),136.42) -> 136.42 | J10: =IFERROR(__xludf.DUMMYFUNCTION("""COMPUTED_VALUE"""),255.83) -> 255.83 | K10: =IFERROR(__xludf.DUMMYFUNCTION("""COMPUTED_VALUE"""),141.93) -> 141.93 | L10: =IFERROR(__xludf.DUMMYFUNCTION("""COMPUTED_VALUE"""),100.6) -> 100.6 | M10: =IFERROR(__xludf.DUMMYFUNCTION("""COMPUTED_VALUE"""),64.64) -> 64.64 | N10: =IFERROR(__xludf.DUMMYFUNCTION("""COMPUTED_VALUE"""),65.94) -> 65.94 | O10: =IFERROR(__xludf.DUMMYFUNCTION("""COMPUTED_VALUE"""),70.52) -> 70.52 | P10: =IFERROR(__xludf.DUMMYFUNCTION("""COMPUTED_VALUE"""),63.35) -> 63.35 | Q10: =IFERROR(__xludf.DUMMYFUNCTION("""COMPUTED_VALUE"""),88.55) -> 88.55 | R10: =IFERROR(__xludf.DUMMYFUNCTION("""COMPUTED_VALUE"""),90.26) -> 90.26 | S10: =IFERROR(__xludf.DUMMYFUNCTION("""COMPUTED_VALUE"""),47.54) -> 47.54 | T10: =IFERROR(__xludf.DUMMYFUNCTION("""COMPUTED_VALUE"""),21.73) -> 21.73 | U10: =IFERROR(__xludf.DUMMYFUNCTION("""COMPUTED_VALUE"""),58.91) -> 58.91 | V10: =IFERROR(__xludf.DUMMYFUNCTION("""COMPUTED_VALUE"""),72.23) -> 72.23 | W10: =IFERROR(__xludf.DUMMYFUNCTION("""COMPUTED_VALUE"""),41.42) -> 41.42 | X10: =IFERROR(__xludf.DUMMYFUNCTION("""COMPUTED_VALUE"""),101.75) -> 101.75 | Y10: =IFERROR(__xludf.DUMMYFUNCTION("""COMPUTED_VALUE"""),59.79) -> 59.79 | Z10: =IFERROR(__xludf.DUMMYFUNCTION("""COMPUTED_VALUE"""),91.32) -> 91.32 | AA10: =IFERROR(__xludf.DUMMYFUNCTION("""COMPUTED_VALUE"""),49.03) -> 49.03 | AB10: =IFERROR(__xludf.DUMMYFUNCTION("""COMPUTED_VALUE"""),77.63) -> 77.63 | AC10: =IFERROR(__xludf.DUMMYFUNCTION("""COMPUTED_VALUE"""),67.65) -> 67.65 | AD10: =IFERROR(__xludf.DUMMYFUNCTION("""COMPUTED_VALUE"""),17.08) -> 17.08 | AE10: =IFERROR(__xludf.DUMMYFUNCTION("""COMPUTED_VALUE"""),27.62) -> 27.62 | AF10: =IFERROR(__xludf.DUMMYFUNCTION("""COMPUTED_VALUE"""),7.13) -> 7.13 | AG10: =IFERROR(__xludf.DUMMYFUNCTION("""COMPUTED_VALUE"""),83.76) -> 83.76
A11: =IFERROR(__xludf.DUMMYFUNCTION("""COMPUTED_VALUE"""),44574.6666666666) -> 44574.667 | B11: =IFERROR(__xludf.DUMMYFUNCTION("""COMPUTED_VALUE"""),164.37) -> 164.37 | C11: =IFERROR(__xludf.DUMMYFUNCTION("""COMPUTED_VALUE"""),430) -> 430 | D11: =IFERROR(__xludf.DUMMYFUNCTION("""COMPUTED_VALUE"""),107.58) -> 107.58 | E11: =IFERROR(__xludf.DUMMYFUNCTION("""COMPUTED_VALUE"""),174.22) -> 174.22 | F11: =IFERROR(__xludf.DUMMYFUNCTION("""COMPUTED_VALUE"""),57.13) -> 57.13 | G11: =IFERROR(__xludf.DUMMYFUNCTION("""COMPUTED_VALUE"""),32.74) -> 32.74 | H11: =IFERROR(__xludf.DUMMYFUNCTION("""COMPUTED_VALUE"""),31.12) -> 31.12 | I11: =IFERROR(__xludf.DUMMYFUNCTION("""COMPUTED_VALUE"""),134.3) -> 134.3 | J11: =IFERROR(__xludf.DUMMYFUNCTION("""COMPUTED_VALUE"""),251.4) -> 251.4 | K11: =IFERROR(__xludf.DUMMYFUNCTION("""COMPUTED_VALUE"""),138.05) -> 138.05 | L11: =IFERROR(__xludf.DUMMYFUNCTION("""COMPUTED_VALUE"""),98.1) -> 98.1 | M11: =IFERROR(__xludf.DUMMYFUNCTION("""COMPUTED_VALUE"""),63) -> 63 | N11: =IFERROR(__xludf.DUMMYFUNCTION("""COMPUTED_VALUE"""),64.78) -> 64.78 | O11: =IFERROR(__xludf.DUMMYFUNCTION("""COMPUTED_VALUE"""),68.12) -> 68.12 | P11: =IFERROR(__xludf.DUMMYFUNCTION("""COMPUTED_VALUE"""),63.03) -> 63.03 | Q11: =IFERROR(__xludf.DUMMYFUNCTION("""COMPUTED_VALUE"""),87.83) -> 87.83 | R11: =IFERROR(__xludf.DUMMYFUNCTION("""COMPUTED_VALUE"""),89.56) -> 89.56 | S11: =IFERROR(__xludf.DUMMYFUNCTION("""COMPUTED_VALUE"""),46.77) -> 46.77 | T11: =IFERROR(__xludf.DUMMYFUNCTION("""COMPUTED_VALUE"""),21.5) -> 21.5 | U11: =IFERROR(__xludf.DUMMYFUNCTION("""COMPUTED_VALUE"""),58.27) -> 58.27 | V11: =IFERROR(__xludf.DUMMYFUNCTION("""COMPUTED_VALUE"""),70.63) -> 70.63 | W11: =IFERROR(__xludf.DUMMYFUNCTION("""COMPUTED_VALUE"""),41.26) -> 41.26 | X11: =IFERROR(__xludf.DUMMYFUNCTION("""COMPUTED_VALUE"""),101.35) -> 101.35 | Y11: =IFERROR(__xludf.DUMMYFUNCTION("""COMPUTED_VALUE"""),60.04) -> 60.04 | Z11: =IFERROR(__xludf.DUMMYFUNCTION("""COMPUTED_VALUE"""),90.89) -> 90.89 | AA11: =IFERROR(__xludf.DUMMYFUNCTION("""COMPUTED_VALUE"""),48.86) -> 48.86 | AB11: =IFERROR(__xludf.DUMMYFUNCTION("""COMPUTED_VALUE"""),78.09) -> 78.09 | AC11: =IFERROR(__xludf.DUMMYFUNCTION("""COMPUTED_VALUE"""),67.27) -> 67.27 | AD11: =IFERROR(__xludf.DUMMYFUNCTION("""COMPUTED_VALUE"""),16.65) -> 16.65 | AE11: =IFERROR(__xludf.DUMMYFUNCTION("""COMPUTED_VALUE"""),26.96) -> 26.96 | AF11: =IFERROR(__xludf.DUMMYFUNCTION("""COMPUTED_VALUE"""),6.83) -> 6.83 | AG11: =IFERROR(__xludf.DUMMYFUNCTION("""COMPUTED_VALUE"""),79.36) -> 79.36
A12: =IFERROR(__xludf.DUMMYFUNCTION("""COMPUTED_VALUE"""),44575.6666666666) -> 44575.667 | B12: =IFERROR(__xludf.DUMMYFUNCTION("""COMPUTED_VALUE"""),165.76) -> 165.76 | C12: =IFERROR(__xludf.DUMMYFUNCTION("""COMPUTED_VALUE"""),433.47) -> 433.47 | D12: =IFERROR(__xludf.DUMMYFUNCTION("""COMPUTED_VALUE"""),108.66) -> 108.66 | E12: =IFERROR(__xludf.DUMMYFUNCTION("""COMPUTED_VALUE"""),178.39) -> 178.39 | F12: =IFERROR(__xludf.DUMMYFUNCTION("""COMPUTED_VALUE"""),57.29) -> 57.29 | G12: =IFERROR(__xludf.DUMMYFUNCTION("""COMPUTED_VALUE"""),32.18) -> 32.18 | H12: =IFERROR(__xludf.DUMMYFUNCTION("""COMPUTED_VALUE"""),31.02) -> 31.02 | I12: =IFERROR(__xludf.DUMMYFUNCTION("""COMPUTED_VALUE"""),134.07) -> 134.07 | J12: =IFERROR(__xludf.DUMMYFUNCTION("""COMPUTED_VALUE"""),251.22) -> 251.22 | K12: =IFERROR(__xludf.DUMMYFUNCTION("""COMPUTED_VALUE"""),138.95) -> 138.95 | L12: =IFERROR(__xludf.DUMMYFUNCTION("""COMPUTED_VALUE"""),100.49) -> 100.49 | M12: =IFERROR(__xludf.DUMMYFUNCTION("""COMPUTED_VALUE"""),63.94) -> 63.94 | N12: =IFERROR(__xludf.DUMMYFUNCTION("""COMPUTED_VALUE"""),64.72) -> 64.72 | O12: =IFERROR(__xludf.DUMMYFUNCTION("""COMPUTED_VALUE"""),68.88) -> 68.88 | P12: =IFERROR(__xludf.DUMMYFUNCTION("""COMPUTED_VALUE"""),64.51) -> 64.51 | Q12: =IFERROR(__xludf.DUMMYFUNCTION("""COMPUTED_VALUE"""),90.05) -> 90.05 | R12: =IFERROR(__xludf.DUMMYFUNCTION("""COMPUTED_VALUE"""),88.8) -> 88.8 | S12: =IFERROR(__xludf.DUMMYFUNCTION("""COMPUTED_VALUE"""),46.98) -> 46.98 | T12: =IFERROR(__xludf.DUMMYFUNCTION("""COMPUTED_VALUE"""),21.78) -> 21.78 | U12: =IFERROR(__xludf.DUMMYFUNCTION("""COMPUTED_VALUE"""),59.97) -> 59.97 | V12: =IFERROR(__xludf.DUMMYFUNCTION("""COMPUTED_VALUE"""),70.45) -> 70.45 | W12: =IFERROR(__xludf.DUMMYFUNCTION("""COMPUTED_VALUE"""),40.83) -> 40.83 | X12: =IFERROR(__xludf.DUMMYFUNCTION("""COMPUTED_VALUE"""),100.46) -> 100.46 | Y12: =IFERROR(__xludf.DUMMYFUNCTION("""COMPUTED_VALUE"""),60.41) -> 60.41 | Z12: =IFERROR(__xludf.DUMMYFUNCTION("""COMPUTED_VALUE"""),90.16) -> 90.16 | AA12: =IFERROR(__xludf.DUMMYFUNCTION("""COMPUTED_VALUE"""),48.29) -> 48.29 | AB12: =IFERROR(__xludf.DUMMYFUNCTION("""COMPUTED_VALUE"""),78.78) -> 78.78 | AC12: =IFERROR(__xludf.DUMMYFUNCTION("""COMPUTED_VALUE"""),66.53) -> 66.53 | AD12: =IFERROR(__xludf.DUMMYFUNCTION("""COMPUTED_VALUE"""),16.81) -> 16.81 | AE12: =IFERROR(__xludf.DUMMYFUNCTION("""COMPUTED_VALUE"""),27.17) -> 27.17 | AF12: =IFERROR(__xludf.DUMMYFUNCTION("""COMPUTED_VALUE"""),6.9) -> 6.9 | AG12: =IFERROR(__xludf.DUMMYFUNCTION("""COMPUTED_VALUE"""),80.44) -> 80.44
A13: =IFERROR(__xludf.DUMMYFUNCTION("""COMPUTED_VALUE"""),44579.6666666666) -> 44579.667 | B13: =IFERROR(__xludf.DUMMYFUNCTION("""COMPUTED_VALUE"""),161.78) -> 161.78 | C13: =IFERROR(__xludf.DUMMYFUNCTION("""COMPUTED_VALUE"""),422.41) -> 422.41 | D13: =IFERROR(__xludf.DUMMYFUNCTION("""COMPUTED_VALUE"""),105.67) -> 105.67 | E13: =IFERROR(__xludf.DUMMYFUNCTION("""COMPUTED_VALUE"""),170.41) -> 170.41 | F13: =IFERROR(__xludf.DUMMYFUNCTION("""COMPUTED_VALUE"""),56.1) -> 56.1 | G13: =IFERROR(__xludf.DUMMYFUNCTION("""COMPUTED_VALUE"""),31.23) -> 31.23 | H13: =IFERROR(__xludf.DUMMYFUNCTION("""COMPUTED_VALUE"""),30.19) -> 30.19 | I13: =IFERROR(__xludf.DUMMYFUNCTION("""COMPUTED_VALUE"""),132.19) -> 132.19 | J13: =IFERROR(__xludf.DUMMYFUNCTION("""COMPUTED_VALUE"""),246.47) -> 246.47 | K13: =IFERROR(__xludf.DUMMYFUNCTION("""COMPUTED_VALUE"""),133.46) -> 133.46 | L13: =IFERROR(__xludf.DUMMYFUNCTION("""COMPUTED_VALUE"""),94.52) -> 94.52 | M13: =IFERROR(__xludf.DUMMYFUNCTION("""COMPUTED_VALUE"""),61.43) -> 61.43 | N13: =IFERROR(__xludf.DUMMYFUNCTION("""COMPUTED_VALUE"""),63.56) -> 63.56 | O13: =IFERROR(__xludf.DUMMYFUNCTION("""COMPUTED_VALUE"""),64.96) -> 64.96 | P13: =IFERROR(__xludf.DUMMYFUNCTION("""COMPUTED_VALUE"""),64.77) -> 64.77 | Q13: =IFERROR(__xludf.DUMMYFUNCTION("""COMPUTED_VALUE"""),90.15) -> 90.15 | R13: =IFERROR(__xludf.DUMMYFUNCTION("""COMPUTED_VALUE"""),87.63) -> 87.63 | S13: =IFERROR(__xludf.DUMMYFUNCTION("""COMPUTED_VALUE"""),46.21) -> 46.21 | T13: =IFERROR(__xludf.DUMMYFUNCTION("""COMPUTED_VALUE"""),21.95) -> 21.95 | U13: =IFERROR(__xludf.DUMMYFUNCTION("""COMPUTED_VALUE"""),60.97) -> 60.97 | V13: =IFERROR(__xludf.DUMMYFUNCTION("""COMPUTED_VALUE"""),67.43) -> 67.43 | W13: =IFERROR(__xludf.DUMMYFUNCTION("""COMPUTED_VALUE"""),39.92) -> 39.92 | X13: =IFERROR(__xludf.DUMMYFUNCTION("""COMPUTED_VALUE"""),98.22) -> 98.22 | Y13: =IFERROR(__xludf.DUMMYFUNCTION("""COMPUTED_VALUE"""),59.22) -> 59.22 | Z13: =IFERROR(__xludf.DUMMYFUNCTION("""COMPUTED_VALUE"""),88.23) -> 88.23 | AA13: =IFERROR(__xludf.DUMMYFUNCTION("""COMPUTED_VALUE"""),47.96) -> 47.96 | AB13: =IFERROR(__xludf.DUMMYFUNCTION("""COMPUTED_VALUE"""),77.11) -> 77.11 | AC13: =IFERROR(__xludf.DUMMYFUNCTION("""COMPUTED_VALUE"""),64.97) -> 64.97 | AD13: =IFERROR(__xludf.DUMMYFUNCTION("""COMPUTED_VALUE"""),16.25) -> 16.25 | AE13: =IFERROR(__xludf.DUMMYFUNCTION("""COMPUTED_VALUE"""),26.28) -> 26.28 | AF13: =IFERROR(__xludf.DUMMYFUNCTION("""COMPUTED_VALUE"""),6.84) -> 6.84 | AG13: =IFERROR(__xludf.DUMMYFUNCTION("""COMPUTED_VALUE"""),75.32) -> 75.32
A14: =IFERROR(__xludf.DUMMYFUNCTION("""COMPUTED_VALUE"""),44580.6666666666) -> 44580.667 | B14: =IFERROR(__xludf.DUMMYFUNCTION("""COMPUTED_VALUE"""),159.52) -> 159.52 | C14: =IFERROR(__xludf.DUMMYFUNCTION("""COMPUTED_VALUE"""),416.52) -> 416.52 | D14: =IFERROR(__xludf.DUMMYFUNCTION("""COMPUTED_VALUE"""),104.37) -> 104.37 | E14: =IFERROR(__xludf.DUMMYFUNCTION("""COMPUTED_VALUE"""),165.4) -> 165.4 | F14: =IFERROR(__xludf.DUMMYFUNCTION("""COMPUTED_VALUE"""),55.89) -> 55.89 | G14: =IFERROR(__xludf.DUMMYFUNCTION("""COMPUTED_VALUE"""),30.8) -> 30.8 | H14: =IFERROR(__xludf.DUMMYFUNCTION("""COMPUTED_VALUE"""),29.93) -> 29.93 | I14: =IFERROR(__xludf.DUMMYFUNCTION("""COMPUTED_VALUE"""),131.65) -> 131.65 | J14: =IFERROR(__xludf.DUMMYFUNCTION("""COMPUTED_VALUE"""),245.42) -> 245.42 | K14: =IFERROR(__xludf.DUMMYFUNCTION("""COMPUTED_VALUE"""),131.83) -> 131.83 | L14: =IFERROR(__xludf.DUMMYFUNCTION("""COMPUTED_VALUE"""),93.5) -> 93.5 | M14: =IFERROR(__xludf.DUMMYFUNCTION("""COMPUTED_VALUE"""),60.65) -> 60.65 | N14: =IFERROR(__xludf.DUMMYFUNCTION("""COMPUTED_VALUE"""),63.28) -> 63.28 | O14: =IFERROR(__xludf.DUMMYFUNCTION("""COMPUTED_VALUE"""),64.24) -> 64.24 | P14: =IFERROR(__xludf.DUMMYFUNCTION("""COMPUTED_VALUE"""),64.3) -> 64.3 | Q14: =IFERROR(__xludf.DUMMYFUNCTION("""COMPUTED_VALUE"""),89.39) -> 89.39 | R14: =IFERROR(__xludf.DUMMYFUNCTION("""COMPUTED_VALUE"""),87.41) -> 87.41 | S14: =IFERROR(__xludf.DUMMYFUNCTION("""COMPUTED_VALUE"""),46.18) -> 46.18 | T14: =IFERROR(__xludf.DUMMYFUNCTION("""COMPUTED_VALUE"""),22.07) -> 22.07 | U14: =IFERROR(__xludf.DUMMYFUNCTION("""COMPUTED_VALUE"""),61.05) -> 61.05 | V14: =IFERROR(__xludf.DUMMYFUNCTION("""COMPUTED_VALUE"""),66.94) -> 66.94 | W14: =IFERROR(__xludf.DUMMYFUNCTION("""COMPUTED_VALUE"""),39.25) -> 39.25 | X14: =IFERROR(__xludf.DUMMYFUNCTION("""COMPUTED_VALUE"""),96.46) -> 96.46 | Y14: =IFERROR(__xludf.DUMMYFUNCTION("""COMPUTED_VALUE"""),57.57) -> 57.57 | Z14: =IFERROR(__xludf.DUMMYFUNCTION("""COMPUTED_VALUE"""),86.69) -> 86.69 | AA14: =IFERROR(__xludf.DUMMYFUNCTION("""COMPUTED_VALUE"""),47.34) -> 47.34 | AB14: =IFERROR(__xludf.DUMMYFUNCTION("""COMPUTED_VALUE"""),75.01) -> 75.01 | AC14: =IFERROR(__xludf.DUMMYFUNCTION("""COMPUTED_VALUE"""),63.92) -> 63.92 | AD14: =IFERROR(__xludf.DUMMYFUNCTION("""COMPUTED_VALUE"""),16.2) -> 16.2 | AE14: =IFERROR(__xludf.DUMMYFUNCTION("""COMPUTED_VALUE"""),26.2) -> 26.2 | AF14: =IFERROR(__xludf.DUMMYFUNCTION("""COMPUTED_VALUE"""),6.41) -> 6.41 | AG14: =IFERROR(__xludf.DUMMYFUNCTION("""COMPUTED_VALUE"""),72.84) -> 72.84
A15: =IFERROR(__xludf.DUMMYFUNCTION("""COMPUTED_VALUE"""),44581.6666666666) -> 44581.667 | B15: =IFERROR(__xludf.DUMMYFUNCTION("""COMPUTED_VALUE"""),157.46) -> 157.46 | C15: =IFERROR(__xludf.DUMMYFUNCTION("""COMPUTED_VALUE"""),411.34) -> 411.34 | D15: =IFERROR(__xludf.DUMMYFUNCTION("""COMPUTED_VALUE"""),102.91) -> 102.91 | E15: =IFERROR(__xludf.DUMMYFUNCTION("""COMPUTED_VALUE"""),160.21) -> 160.21 | F15: =IFERROR(__xludf.DUMMYFUNCTION("""COMPUTED_VALUE"""),55.74) -> 55.74 | G15: =IFERROR(__xludf.DUMMYFUNCTION("""COMPUTED_VALUE"""),30.55) -> 30.55 | H15: =IFERROR(__xludf.DUMMYFUNCTION("""COMPUTED_VALUE"""),29.58) -> 29.58 | I15: =IFERROR(__xludf.DUMMYFUNCTION("""COMPUTED_VALUE"""),130.79) -> 130.79 | J15: =IFERROR(__xludf.DUMMYFUNCTION("""COMPUTED_VALUE"""),243.97) -> 243.97 | K15: =IFERROR(__xludf.DUMMYFUNCTION("""COMPUTED_VALUE"""),130.65) -> 130.65 | L15: =IFERROR(__xludf.DUMMYFUNCTION("""COMPUTED_VALUE"""),91.97) -> 91.97 | M15: =IFERROR(__xludf.DUMMYFUNCTION("""COMPUTED_VALUE"""),59.7) -> 59.7 | N15: =IFERROR(__xludf.DUMMYFUNCTION("""COMPUTED_VALUE"""),62.85) -> 62.85 | O15: =IFERROR(__xludf.DUMMYFUNCTION("""COMPUTED_VALUE"""),63.84) -> 63.84 | P15: =IFERROR(__xludf.DUMMYFUNCTION("""COMPUTED_VALUE"""),63.71) -> 63.71 | Q15: =IFERROR(__xludf.DUMMYFUNCTION("""COMPUTED_VALUE"""),88.29) -> 88.29 | R15: =IFERROR(__xludf.DUMMYFUNCTION("""COMPUTED_VALUE"""),86.14) -> 86.14 | S15: =IFERROR(__xludf.DUMMYFUNCTION("""COMPUTED_VALUE"""),44.5) -> 44.5 | T15: =IFERROR(__xludf.DUMMYFUNCTION("""COMPUTED_VALUE"""),21.99) -> 21.99 | U15: =IFERROR(__xludf.DUMMYFUNCTION("""COMPUTED_VALUE"""),60.66) -> 60.66 | V15: =IFERROR(__xludf.DUMMYFUNCTION("""COMPUTED_VALUE"""),66.99) -> 66.99 | W15: =IFERROR(__xludf.DUMMYFUNCTION("""COMPUTED_VALUE"""),39) -> 39 | X15: =IFERROR(__xludf.DUMMYFUNCTION("""COMPUTED_VALUE"""),95.68) -> 95.68 | Y15: =IFERROR(__xludf.DUMMYFUNCTION("""COMPUTED_VALUE"""),56.24) -> 56.24 | Z15: =IFERROR(__xludf.DUMMYFUNCTION("""COMPUTED_VALUE"""),86.13) -> 86.13 | AA15: =IFERROR(__xludf.DUMMYFUNCTION("""COMPUTED_VALUE"""),46.92) -> 46.92 | AB15: =IFERROR(__xludf.DUMMYFUNCTION("""COMPUTED_VALUE"""),73.04) -> 73.04 | AC15: =IFERROR(__xludf.DUMMYFUNCTION("""COMPUTED_VALUE"""),63.55) -> 63.55 | AD15: =IFERROR(__xludf.DUMMYFUNCTION("""COMPUTED_VALUE"""),16.63) -> 16.63 | AE15: =IFERROR(__xludf.DUMMYFUNCTION("""COMPUTED_VALUE"""),26.9) -> 26.9 | AF15: =IFERROR(__xludf.DUMMYFUNCTION("""COMPUTED_VALUE"""),6.32) -> 6.32 | AG15: =IFERROR(__xludf.DUMMYFUNCTION("""COMPUTED_VALUE"""),73.56) -> 73.56
A16: =IFERROR(__xludf.DUMMYFUNCTION("""COMPUTED_VALUE"""),44582.6666666666) -> 44582.667 | B16: =IFERROR(__xludf.DUMMYFUNCTION("""COMPUTED_VALUE"""),154.33) -> 154.33 | C16: =IFERROR(__xludf.DUMMYFUNCTION("""COMPUTED_VALUE"""),402.43) -> 402.43 | D16: =IFERROR(__xludf.DUMMYFUNCTION("""COMPUTED_VALUE"""),100.62) -> 100.62 | E16: =IFERROR(__xludf.DUMMYFUNCTION("""COMPUTED_VALUE"""),157.55) -> 157.55 | F16: =IFERROR(__xludf.DUMMYFUNCTION("""COMPUTED_VALUE"""),54.63) -> 54.63 | G16: =IFERROR(__xludf.DUMMYFUNCTION("""COMPUTED_VALUE"""),29.49) -> 29.49 | H16: =IFERROR(__xludf.DUMMYFUNCTION("""COMPUTED_VALUE"""),28.78) -> 28.78 | I16: =IFERROR(__xludf.DUMMYFUNCTION("""COMPUTED_VALUE"""),129.47) -> 129.47 | J16: =IFERROR(__xludf.DUMMYFUNCTION("""COMPUTED_VALUE"""),241.39) -> 241.39 | K16: =IFERROR(__xludf.DUMMYFUNCTION("""COMPUTED_VALUE"""),128.68) -> 128.68 | L16: =IFERROR(__xludf.DUMMYFUNCTION("""COMPUTED_VALUE"""),90.03) -> 90.03 | M16: =IFERROR(__xludf.DUMMYFUNCTION("""COMPUTED_VALUE"""),58.98) -> 58.98 | N16: =IFERROR(__xludf.DUMMYFUNCTION("""COMPUTED_VALUE"""),62.14) -> 62.14 | O16: =IFERROR(__xludf.DUMMYFUNCTION("""COMPUTED_VALUE"""),62.56) -> 62.56 | P16: =IFERROR(__xludf.DUMMYFUNCTION("""COMPUTED_VALUE"""),62.45) -> 62.45 | Q16: =IFERROR(__xludf.DUMMYFUNCTION("""COMPUTED_VALUE"""),86.41) -> 86.41 | R16: =IFERROR(__xludf.DUMMYFUNCTION("""COMPUTED_VALUE"""),84.04) -> 84.04 | S16: =IFERROR(__xludf.DUMMYFUNCTION("""COMPUTED_VALUE"""),42.27) -> 42.27 | T16: =IFERROR(__xludf.DUMMYFUNCTION("""COMPUTED_VALUE"""),22.01) -> 22.01 | U16: =IFERROR(__xludf.DUMMYFUNCTION("""COMPUTED_VALUE"""),60.78) -> 60.78 | V16: =IFERROR(__xludf.DUMMYFUNCTION("""COMPUTED_VALUE"""),63.74) -> 63.74 | W16: =IFERROR(__xludf.DUMMYFUNCTION("""COMPUTED_VALUE"""),38.2) -> 38.2 | X16: =IFERROR(__xludf.DUMMYFUNCTION("""COMPUTED_VALUE"""),93.85) -> 93.85 | Y16: =IFERROR(__xludf.DUMMYFUNCTION("""COMPUTED_VALUE"""),55.12) -> 55.12 | Z16: =IFERROR(__xludf.DUMMYFUNCTION("""COMPUTED_VALUE"""),84.38) -> 84.38 | AA16: =IFERROR(__xludf.DUMMYFUNCTION("""COMPUTED_VALUE"""),46.89) -> 46.89 | AB16: =IFERROR(__xludf.DUMMYFUNCTION("""COMPUTED_VALUE"""),71.61) -> 71.61 | AC16: =IFERROR(__xludf.DUMMYFUNCTION("""COMPUTED_VALUE"""),62.07) -> 62.07 | AD16: =IFERROR(__xludf.DUMMYFUNCTION("""COMPUTED_VALUE"""),14.91) -> 14.91 | AE16: =IFERROR(__xludf.DUMMYFUNCTION("""COMPUTED_VALUE"""),24.1) -> 24.1 | AF16: =IFERROR(__xludf.DUMMYFUNCTION("""COMPUTED_VALUE"""),5.95) -> 5.95 | AG16: =IFERROR(__xludf.DUMMYFUNCTION("""COMPUTED_VALUE"""),64.52) -> 64.52
A17: =IFERROR(__xludf.DUMMYFUNCTION("""COMPUTED_VALUE"""),44585.6666666666) -> 44585.667 | B17: =IFERROR(__xludf.DUMMYFUNCTION("""COMPUTED_VALUE"""),155.13) -> 155.13 | C17: =IFERROR(__xludf.DUMMYFUNCTION("""COMPUTED_VALUE"""),405.03) -> 405.03 | D17: =IFERROR(__xludf.DUMMYFUNCTION("""COMPUTED_VALUE"""),101.63) -> 101.63 | E17: =IFERROR(__xludf.DUMMYFUNCTION("""COMPUTED_VALUE"""),159.35) -> 159.35 | F17: =IFERROR(__xludf.DUMMYFUNCTION("""COMPUTED_VALUE"""),55.16) -> 55.16 | G17: =IFERROR(__xludf.DUMMYFUNCTION("""COMPUTED_VALUE"""),29.3) -> 29.3 | H17: =IFERROR(__xludf.DUMMYFUNCTION("""COMPUTED_VALUE"""),29.13) -> 29.13 | I17: =IFERROR(__xludf.DUMMYFUNCTION("""COMPUTED_VALUE"""),129.04) -> 129.04 | J17: =IFERROR(__xludf.DUMMYFUNCTION("""COMPUTED_VALUE"""),241.11) -> 241.11 | K17: =IFERROR(__xludf.DUMMYFUNCTION("""COMPUTED_VALUE"""),129.86) -> 129.86 | L17: =IFERROR(__xludf.DUMMYFUNCTION("""COMPUTED_VALUE"""),92.11) -> 92.11 | M17: =IFERROR(__xludf.DUMMYFUNCTION("""COMPUTED_VALUE"""),59.88) -> 59.88 | N17: =IFERROR(__xludf.DUMMYFUNCTION("""COMPUTED_VALUE"""),62.11) -> 62.11 | O17: =IFERROR(__xludf.DUMMYFUNCTION("""COMPUTED_VALUE"""),63.6) -> 63.6 | P17: =IFERROR(__xludf.DUMMYFUNCTION("""COMPUTED_VALUE"""),62.87) -> 62.87 | Q17: =IFERROR(__xludf.DUMMYFUNCTION("""COMPUTED_VALUE"""),87.06) -> 87.06 | R17: =IFERROR(__xludf.DUMMYFUNCTION("""COMPUTED_VALUE"""),84.09) -> 84.09 | S17: =IFERROR(__xludf.DUMMYFUNCTION("""COMPUTED_VALUE"""),42.66) -> 42.66 | T17: =IFERROR(__xludf.DUMMYFUNCTION("""COMPUTED_VALUE"""),21.96) -> 21.96 | U17: =IFERROR(__xludf.DUMMYFUNCTION("""COMPUTED_VALUE"""),60.11) -> 60.11 | V17: =IFERROR(__xludf.DUMMYFUNCTION("""COMPUTED_VALUE"""),64.42) -> 64.42 | W17: =IFERROR(__xludf.DUMMYFUNCTION("""COMPUTED_VALUE"""),38.31) -> 38.31 | X17: =IFERROR(__xludf.DUMMYFUNCTION("""COMPUTED_VALUE"""),94.19) -> 94.19 | Y17: =IFERROR(__xludf.DUMMYFUNCTION("""COMPUTED_VALUE"""),55.7) -> 55.7 | Z17: =IFERROR(__xludf.DUMMYFUNCTION("""COMPUTED_VALUE"""),84.66) -> 84.66 | AA17: =IFERROR(__xludf.DUMMYFUNCTION("""COMPUTED_VALUE"""),46.99) -> 46.99 | AB17: =IFERROR(__xludf.DUMMYFUNCTION("""COMPUTED_VALUE"""),72.61) -> 72.61 | AC17: =IFERROR(__xludf.DUMMYFUNCTION("""COMPUTED_VALUE"""),61.94) -> 61.94 | AD17: =IFERROR(__xludf.DUMMYFUNCTION("""COMPUTED_VALUE"""),14.49) -> 14.49 | AE17: =IFERROR(__xludf.DUMMYFUNCTION("""COMPUTED_VALUE"""),23.48) -> 23.48 | AF17: =IFERROR(__xludf.DUMMYFUNCTION("""COMPUTED_VALUE"""),5.37) -> 5.37 | AG17: =IFERROR(__xludf.DUMMYFUNCTION("""COMPUTED_VALUE"""),63.32) -> 63.32
A18: =IFERROR(__xludf.DUMMYFUNCTION("""COMPUTED_VALUE"""),44586.6666666666) -> 44586.667 | B18: =IFERROR(__xludf.DUMMYFUNCTION("""COMPUTED_VALUE"""),151.54) -> 151.54 | C18: =IFERROR(__xludf.DUMMYFUNCTION("""COMPUTED_VALUE"""),395.08) -> 395.08 | D18: =IFERROR(__xludf.DUMMYFUNCTION("""COMPUTED_VALUE"""),98.76) -> 98.76 | E18: =IFERROR(__xludf.DUMMYFUNCTION("""COMPUTED_VALUE"""),153.4) -> 153.4 | F18: =IFERROR(__xludf.DUMMYFUNCTION("""COMPUTED_VALUE"""),53.43) -> 53.43 | G18: =IFERROR(__xludf.DUMMYFUNCTION("""COMPUTED_VALUE"""),28.81) -> 28.81 | H18: =IFERROR(__xludf.DUMMYFUNCTION("""COMPUTED_VALUE"""),28.47) -> 28.47 | I18: =IFERROR(__xludf.DUMMYFUNCTION("""COMPUTED_VALUE"""),128.21) -> 128.21 | J18: =IFERROR(__xludf.DUMMYFUNCTION("""COMPUTED_VALUE"""),238.85) -> 238.85 | K18: =IFERROR(__xludf.DUMMYFUNCTION("""COMPUTED_VALUE"""),127.59) -> 127.59 | L18: =IFERROR(__xludf.DUMMYFUNCTION("""COMPUTED_VALUE"""),91.38) -> 91.38 | M18: =IFERROR(__xludf.DUMMYFUNCTION("""COMPUTED_VALUE"""),58.99) -> 58.99 | N18: =IFERROR(__xludf.DUMMYFUNCTION("""COMPUTED_VALUE"""),61.56) -> 61.56 | O18: =IFERROR(__xludf.DUMMYFUNCTION("""COMPUTED_VALUE"""),62.48) -> 62.48 | P18: =IFERROR(__xludf.DUMMYFUNCTION("""COMPUTED_VALUE"""),65.31) -> 65.31 | Q18: =IFERROR(__xludf.DUMMYFUNCTION("""COMPUTED_VALUE"""),90.29) -> 90.29 | R18: =IFERROR(__xludf.DUMMYFUNCTION("""COMPUTED_VALUE"""),83.33) -> 83.33 | S18: =IFERROR(__xludf.DUMMYFUNCTION("""COMPUTED_VALUE"""),42.8) -> 42.8 | T18: =IFERROR(__xludf.DUMMYFUNCTION("""COMPUTED_VALUE"""),22.16) -> 22.16 | U18: =IFERROR(__xludf.DUMMYFUNCTION("""COMPUTED_VALUE"""),60.97) -> 60.97 | V18: =IFERROR(__xludf.DUMMYFUNCTION("""COMPUTED_VALUE"""),62.37) -> 62.37 | W18: =IFERROR(__xludf.DUMMYFUNCTION("""COMPUTED_VALUE"""),38.47) -> 38.47 | X18: =IFERROR(__xludf.DUMMYFUNCTION("""COMPUTED_VALUE"""),94.49) -> 94.49 | Y18: =IFERROR(__xludf.DUMMYFUNCTION("""COMPUTED_VALUE"""),55.82) -> 55.82 | Z18: =IFERROR(__xludf.DUMMYFUNCTION("""COMPUTED_VALUE"""),84.58) -> 84.58 | AA18: =IFERROR(__xludf.DUMMYFUNCTION("""COMPUTED_VALUE"""),46.86) -> 46.86 | AB18: =IFERROR(__xludf.DUMMYFUNCTION("""COMPUTED_VALUE"""),72.55) -> 72.55 | AC18: =IFERROR(__xludf.DUMMYFUNCTION("""COMPUTED_VALUE"""),62.04) -> 62.04 | AD18: =IFERROR(__xludf.DUMMYFUNCTION("""COMPUTED_VALUE"""),14.38) -> 14.38 | AE18: =IFERROR(__xludf.DUMMYFUNCTION("""COMPUTED_VALUE"""),23.22) -> 23.22 | AF18: =IFERROR(__xludf.DUMMYFUNCTION("""COMPUTED_VALUE"""),5.38) -> 5.38 | AG18: =IFERROR(__xludf.DUMMYFUNCTION("""COMPUTED_VALUE"""),62.64) -> 62.64
A19: =IFERROR(__xludf.DUMMYFUNCTION("""COMPUTED_VALUE"""),44587.6666666666) -> 44587.667 | B19: =IFERROR(__xludf.DUMMYFUNCTION("""COMPUTED_VALUE"""),152.43) -> 152.43 | C19: =IFERROR(__xludf.DUMMYFUNCTION("""COMPUTED_VALUE"""),396.45) -> 396.45 | D19: =IFERROR(__xludf.DUMMYFUNCTION("""COMPUTED_VALUE"""),99.24) -> 99.24 | E19: =IFERROR(__xludf.DUMMYFUNCTION("""COMPUTED_VALUE"""),155.76) -> 155.76 | F19: =IFERROR(__xludf.DUMMYFUNCTION("""COMPUTED_VALUE"""),53) -> 53 | G19: =IFERROR(__xludf.DUMMYFUNCTION("""COMPUTED_VALUE"""),28.75) -> 28.75 | H19: =IFERROR(__xludf.DUMMYFUNCTION("""COMPUTED_VALUE"""),28.18) -> 28.18 | I19: =IFERROR(__xludf.DUMMYFUNCTION("""COMPUTED_VALUE"""),127.54) -> 127.54 | J19: =IFERROR(__xludf.DUMMYFUNCTION("""COMPUTED_VALUE"""),237.56) -> 237.56 | K19: =IFERROR(__xludf.DUMMYFUNCTION("""COMPUTED_VALUE"""),126.22) -> 126.22 | L19: =IFERROR(__xludf.DUMMYFUNCTION("""COMPUTED_VALUE"""),89.59) -> 89.59 | M19: =IFERROR(__xludf.DUMMYFUNCTION("""COMPUTED_VALUE"""),58.18) -> 58.18 | N19: =IFERROR(__xludf.DUMMYFUNCTION("""COMPUTED_VALUE"""),61.11) -> 61.11 | O19: =IFERROR(__xludf.DUMMYFUNCTION("""COMPUTED_VALUE"""),61.2) -> 61.2 | P19: =IFERROR(__xludf.DUMMYFUNCTION("""COMPUTED_VALUE"""),65.2) -> 65.2 | Q19: =IFERROR(__xludf.DUMMYFUNCTION("""COMPUTED_VALUE"""),90.06) -> 90.06 | R19: =IFERROR(__xludf.DUMMYFUNCTION("""COMPUTED_VALUE"""),82.46) -> 82.46 | S19: =IFERROR(__xludf.DUMMYFUNCTION("""COMPUTED_VALUE"""),41.67) -> 41.67 | T19: =IFERROR(__xludf.DUMMYFUNCTION("""COMPUTED_VALUE"""),22.21) -> 22.21 | U19: =IFERROR(__xludf.DUMMYFUNCTION("""COMPUTED_VALUE"""),61.68) -> 61.68 | V19: =IFERROR(__xludf.DUMMYFUNCTION("""COMPUTED_VALUE"""),62.49) -> 62.49 | W19: =IFERROR(__xludf.DUMMYFUNCTION("""COMPUTED_VALUE"""),38.57) -> 38.57 | X19: =IFERROR(__xludf.DUMMYFUNCTION("""COMPUTED_VALUE"""),94.45) -> 94.45 | Y19: =IFERROR(__xludf.DUMMYFUNCTION("""COMPUTED_VALUE"""),55.45) -> 55.45 | Z19: =IFERROR(__xludf.DUMMYFUNCTION("""COMPUTED_VALUE"""),84.82) -> 84.82 | AA19: =IFERROR(__xludf.DUMMYFUNCTION("""COMPUTED_VALUE"""),46.08) -> 46.08 | AB19: =IFERROR(__xludf.DUMMYFUNCTION("""COMPUTED_VALUE"""),72.15) -> 72.15 | AC19: =IFERROR(__xludf.DUMMYFUNCTION("""COMPUTED_VALUE"""),62.3) -> 62.3 | AD19: =IFERROR(__xludf.DUMMYFUNCTION("""COMPUTED_VALUE"""),14.42) -> 14.42 | AE19: =IFERROR(__xludf.DUMMYFUNCTION("""COMPUTED_VALUE"""),23.25) -> 23.25 | AF19: =IFERROR(__xludf.DUMMYFUNCTION("""COMPUTED_VALUE"""),5.32) -> 5.32 | AG19: =IFERROR(__xludf.DUMMYFUNCTION("""COMPUTED_VALUE"""),62.48) -> 62.48
A20: =IFERROR(__xludf.DUMMYFUNCTION("""COMPUTED_VALUE"""),44588.6666666666) -> 44588.667 | B20: =IFERROR(__xludf.DUMMYFUNCTION("""COMPUTED_VALUE"""),151.38) -> 151.38 | C20: =IFERROR(__xludf.DUMMYFUNCTION("""COMPUTED_VALUE"""),393.09) -> 393.09 | D20: =IFERROR(__xludf.DUMMYFUNCTION("""COMPUTED_VALUE"""),98.38) -> 98.38 | E20: =IFERROR(__xludf.DUMMYFUNCTION("""COMPUTED_VALUE"""),148.82) -> 148.82 | F20: =IFERROR(__xludf.DUMMYFUNCTION("""COMPUTED_VALUE"""),52.39) -> 52.39 | G20: =IFERROR(__xludf.DUMMYFUNCTION("""COMPUTED_VALUE"""),28.08) -> 28.08 | H20: =IFERROR(__xludf.DUMMYFUNCTION("""COMPUTED_VALUE"""),27.74) -> 27.74 | I20: =IFERROR(__xludf.DUMMYFUNCTION("""COMPUTED_VALUE"""),127.87) -> 127.87 | J20: =IFERROR(__xludf.DUMMYFUNCTION("""COMPUTED_VALUE"""),236.85) -> 236.85 | K20: =IFERROR(__xludf.DUMMYFUNCTION("""COMPUTED_VALUE"""),123.68) -> 123.68 | L20: =IFERROR(__xludf.DUMMYFUNCTION("""COMPUTED_VALUE"""),85.51) -> 85.51 | M20: =IFERROR(__xludf.DUMMYFUNCTION("""COMPUTED_VALUE"""),56.78) -> 56.78 | N20: =IFERROR(__xludf.DUMMYFUNCTION("""COMPUTED_VALUE"""),61.05) -> 61.05 | O20: =IFERROR(__xludf.DUMMYFUNCTION("""COMPUTED_VALUE"""),59.36) -> 59.36 | P20: =IFERROR(__xludf.DUMMYFUNCTION("""COMPUTED_VALUE"""),65.91) -> 65.91 | Q20: =IFERROR(__xludf.DUMMYFUNCTION("""COMPUTED_VALUE"""),90.98) -> 90.98 | R20: =IFERROR(__xludf.DUMMYFUNCTION("""COMPUTED_VALUE"""),82.74) -> 82.74 | S20: =IFERROR(__xludf.DUMMYFUNCTION("""COMPUTED_VALUE"""),41.02) -> 41.02 | T20: =IFERROR(__xludf.DUMMYFUNCTION("""COMPUTED_VALUE"""),22.32) -> 22.32 | U20: =IFERROR(__xludf.DUMMYFUNCTION("""COMPUTED_VALUE"""),61.86) -> 61.86 | V20: =IFERROR(__xludf.DUMMYFUNCTION("""COMPUTED_VALUE"""),60.14) -> 60.14 | W20: =IFERROR(__xludf.DUMMYFUNCTION("""COMPUTED_VALUE"""),38.22) -> 38.22 | X20: =IFERROR(__xludf.DUMMYFUNCTION("""COMPUTED_VALUE"""),93.63) -> 93.63 | Y20: =IFERROR(__xludf.DUMMYFUNCTION("""COMPUTED_VALUE"""),54.28) -> 54.28 | Z20: =IFERROR(__xludf.DUMMYFUNCTION("""COMPUTED_VALUE"""),84.18) -> 84.18 | AA20: =IFERROR(__xludf.DUMMYFUNCTION("""COMPUTED_VALUE"""),45.25) -> 45.25 | AB20: =IFERROR(__xludf.DUMMYFUNCTION("""COMPUTED_VALUE"""),70.63) -> 70.63 | AC20: =IFERROR(__xludf.DUMMYFUNCTION("""COMPUTED_VALUE"""),62.01) -> 62.01 | AD20: =IFERROR(__xludf.DUMMYFUNCTION("""COMPUTED_VALUE"""),13.85) -> 13.85 | AE20: =IFERROR(__xludf.DUMMYFUNCTION("""COMPUTED_VALUE"""),22.31) -> 22.31 | AF20: =IFERROR(__xludf.DUMMYFUNCTION("""COMPUTED_VALUE"""),5.3) -> 5.3 | AG20: =IFERROR(__xludf.DUMMYFUNCTION("""COMPUTED_VALUE"""),58.32) -> 58.32
A21: =IFERROR(__xludf.DUMMYFUNCTION("""COMPUTED_VALUE"""),44589.6666666666) -> 44589.667 | B21: =IFERROR(__xludf.DUMMYFUNCTION("""COMPUTED_VALUE"""),158) -> 158 | C21: =IFERROR(__xludf.DUMMYFUNCTION("""COMPUTED_VALUE"""),409.84) -> 409.84 | D21: =IFERROR(__xludf.DUMMYFUNCTION("""COMPUTED_VALUE"""),102.04) -> 102.04 | E21: =IFERROR(__xludf.DUMMYFUNCTION("""COMPUTED_VALUE"""),151.68) -> 151.68 | F21: =IFERROR(__xludf.DUMMYFUNCTION("""COMPUTED_VALUE"""),53.29) -> 53.29 | G21: =IFERROR(__xludf.DUMMYFUNCTION("""COMPUTED_VALUE"""),28.39) -> 28.39 | H21: =IFERROR(__xludf.DUMMYFUNCTION("""COMPUTED_VALUE"""),28.49) -> 28.49 | I21: =IFERROR(__xludf.DUMMYFUNCTION("""COMPUTED_VALUE"""),130.48) -> 130.48 | J21: =IFERROR(__xludf.DUMMYFUNCTION("""COMPUTED_VALUE"""),242.28) -> 242.28 | K21: =IFERROR(__xludf.DUMMYFUNCTION("""COMPUTED_VALUE"""),127.97) -> 127.97 | L21: =IFERROR(__xludf.DUMMYFUNCTION("""COMPUTED_VALUE"""),88.58) -> 88.58 | M21: =IFERROR(__xludf.DUMMYFUNCTION("""COMPUTED_VALUE"""),59.05) -> 59.05 | N21: =IFERROR(__xludf.DUMMYFUNCTION("""COMPUTED_VALUE"""),62.45) -> 62.45 | O21: =IFERROR(__xludf.DUMMYFUNCTION("""COMPUTED_VALUE"""),61.12) -> 61.12 | P21: =IFERROR(__xludf.DUMMYFUNCTION("""COMPUTED_VALUE"""),65.63) -> 65.63 | Q21: =IFERROR(__xludf.DUMMYFUNCTION("""COMPUTED_VALUE"""),90.79) -> 90.79 | R21: =IFERROR(__xludf.DUMMYFUNCTION("""COMPUTED_VALUE"""),83.22) -> 83.22 | S21: =IFERROR(__xludf.DUMMYFUNCTION("""COMPUTED_VALUE"""),41.37) -> 41.37 | T21: =IFERROR(__xludf.DUMMYFUNCTION("""COMPUTED_VALUE"""),22.34) -> 22.34 | U21: =IFERROR(__xludf.DUMMYFUNCTION("""COMPUTED_VALUE"""),61.97) -> 61.97 | V21: =IFERROR(__xludf.DUMMYFUNCTION("""COMPUTED_VALUE"""),60.51) -> 60.51 | W21: =IFERROR(__xludf.DUMMYFUNCTION("""COMPUTED_VALUE"""),38.72) -> 38.72 | X21: =IFERROR(__xludf.DUMMYFUNCTION("""COMPUTED_VALUE"""),94.87) -> 94.87 | Y21: =IFERROR(__xludf.DUMMYFUNCTION("""COMPUTED_VALUE"""),54.58) -> 54.58 | Z21: =IFERROR(__xludf.DUMMYFUNCTION("""COMPUTED_VALUE"""),85.41) -> 85.41 | AA21: =IFERROR(__xludf.DUMMYFUNCTION("""COMPUTED_VALUE"""),46.82) -> 46.82 | AB21: =IFERROR(__xludf.DUMMYFUNCTION("""COMPUTED_VALUE"""),71.01) -> 71.01 | AC21: =IFERROR(__xludf.DUMMYFUNCTION("""COMPUTED_VALUE"""),63.58) -> 63.58 | AD21: =IFERROR(__xludf.DUMMYFUNCTION("""COMPUTED_VALUE"""),14.71) -> 14.71 | AE21: =IFERROR(__xludf.DUMMYFUNCTION("""COMPUTED_VALUE"""),23.77) -> 23.77 | AF21: =IFERROR(__xludf.DUMMYFUNCTION("""COMPUTED_VALUE"""),5.42) -> 5.42 | AG21: =IFERROR(__xludf.DUMMYFUNCTION("""COMPUTED_VALUE"""),61.44) -> 61.44
A22: =IFERROR(__xludf.DUMMYFUNCTION("""COMPUTED_VALUE"""),44592.6666666666) -> 44592.667 | B22: =IFERROR(__xludf.DUMMYFUNCTION("""COMPUTED_VALUE"""),161.97) -> 161.97 | C22: =IFERROR(__xludf.DUMMYFUNCTION("""COMPUTED_VALUE"""),422.26) -> 422.26 | D22: =IFERROR(__xludf.DUMMYFUNCTION("""COMPUTED_VALUE"""),105.26) -> 105.26 | E22: =IFERROR(__xludf.DUMMYFUNCTION("""COMPUTED_VALUE"""),159.82) -> 159.82 | F22: =IFERROR(__xludf.DUMMYFUNCTION("""COMPUTED_VALUE"""),55.19) -> 55.19 | G22: =IFERROR(__xludf.DUMMYFUNCTION("""COMPUTED_VALUE"""),29.7) -> 29.7 | H22: =IFERROR(__xludf.DUMMYFUNCTION("""COMPUTED_VALUE"""),29.59) -> 29.59 | I22: =IFERROR(__xludf.DUMMYFUNCTION("""COMPUTED_VALUE"""),131.23) -> 131.23 | J22: =IFERROR(__xludf.DUMMYFUNCTION("""COMPUTED_VALUE"""),245.34) -> 245.34 | K22: =IFERROR(__xludf.DUMMYFUNCTION("""COMPUTED_VALUE"""),131.86) -> 131.86 | L22: =IFERROR(__xludf.DUMMYFUNCTION("""COMPUTED_VALUE"""),93.43) -> 93.43 | M22: =IFERROR(__xludf.DUMMYFUNCTION("""COMPUTED_VALUE"""),60.73) -> 60.73 | N22: =IFERROR(__xludf.DUMMYFUNCTION("""COMPUTED_VALUE"""),63.22) -> 63.22 | O22: =IFERROR(__xludf.DUMMYFUNCTION("""COMPUTED_VALUE"""),64.56) -> 64.56 | P22: =IFERROR(__xludf.DUMMYFUNCTION("""COMPUTED_VALUE"""),65.92) -> 65.92 | Q22: =IFERROR(__xludf.DUMMYFUNCTION("""COMPUTED_VALUE"""),91.18) -> 91.18 | R22: =IFERROR(__xludf.DUMMYFUNCTION("""COMPUTED_VALUE"""),84.45) -> 84.45 | S22: =IFERROR(__xludf.DUMMYFUNCTION("""COMPUTED_VALUE"""),41.72) -> 41.72 | T22: =IFERROR(__xludf.DUMMYFUNCTION("""COMPUTED_VALUE"""),22.42) -> 22.42 | U22: =IFERROR(__xludf.DUMMYFUNCTION("""COMPUTED_VALUE"""),62.48) -> 62.48 | V22: =IFERROR(__xludf.DUMMYFUNCTION("""COMPUTED_VALUE"""),65.48) -> 65.48 | W22: =IFERROR(__xludf.DUMMYFUNCTION("""COMPUTED_VALUE"""),39.06) -> 39.06 | X22: =IFERROR(__xludf.DUMMYFUNCTION("""COMPUTED_VALUE"""),96.02) -> 96.02 | Y22: =IFERROR(__xludf.DUMMYFUNCTION("""COMPUTED_VALUE"""),55.03) -> 55.03 | Z22: =IFERROR(__xludf.DUMMYFUNCTION("""COMPUTED_VALUE"""),86.36) -> 86.36 | AA22: =IFERROR(__xludf.DUMMYFUNCTION("""COMPUTED_VALUE"""),47.34) -> 47.34 | AB22: =IFERROR(__xludf.DUMMYFUNCTION("""COMPUTED_VALUE"""),71.6) -> 71.6 | AC22: =IFERROR(__xludf.DUMMYFUNCTION("""COMPUTED_VALUE"""),64.3) -> 64.3 | AD22: =IFERROR(__xludf.DUMMYFUNCTION("""COMPUTED_VALUE"""),14.99) -> 14.99 | AE22: =IFERROR(__xludf.DUMMYFUNCTION("""COMPUTED_VALUE"""),24.16) -> 24.16 | AF22: =IFERROR(__xludf.DUMMYFUNCTION("""COMPUTED_VALUE"""),5.86) -> 5.86 | AG22: =IFERROR(__xludf.DUMMYFUNCTION("""COMPUTED_VALUE"""),66.12) -> 66.12
A23: =IFERROR(__xludf.DUMMYFUNCTION("""COMPUTED_VALUE"""),44593.6666666666) -> 44593.667 | B23: =IFERROR(__xludf.DUMMYFUNCTION("""COMPUTED_VALUE"""),162.39) -> 162.39 | C23: =IFERROR(__xludf.DUMMYFUNCTION("""COMPUTED_VALUE"""),424.01) -> 424.01 | D23: =IFERROR(__xludf.DUMMYFUNCTION("""COMPUTED_VALUE"""),105.84) -> 105.84 | E23: =IFERROR(__xludf.DUMMYFUNCTION("""COMPUTED_VALUE"""),161.15) -> 161.15 | F23: =IFERROR(__xludf.DUMMYFUNCTION("""COMPUTED_VALUE"""),55.72) -> 55.72 | G23: =IFERROR(__xludf.DUMMYFUNCTION("""COMPUTED_VALUE"""),30.15) -> 30.15 | H23: =IFERROR(__xludf.DUMMYFUNCTION("""COMPUTED_VALUE"""),29.99) -> 29.99 | I23: =IFERROR(__xludf.DUMMYFUNCTION("""COMPUTED_VALUE"""),131.58) -> 131.58 | J23: =IFERROR(__xludf.DUMMYFUNCTION("""COMPUTED_VALUE"""),246.28) -> 246.28 | K23: =IFERROR(__xludf.DUMMYFUNCTION("""COMPUTED_VALUE"""),134.25) -> 134.25 | L23: =IFERROR(__xludf.DUMMYFUNCTION("""COMPUTED_VALUE"""),94.94) -> 94.94 | M23: =IFERROR(__xludf.DUMMYFUNCTION("""COMPUTED_VALUE"""),61.64) -> 61.64 | N23: =IFERROR(__xludf.DUMMYFUNCTION("""COMPUTED_VALUE"""),63.41) -> 63.41 | O23: =IFERROR(__xludf.DUMMYFUNCTION("""COMPUTED_VALUE"""),66.12) -> 66.12 | P23: =IFERROR(__xludf.DUMMYFUNCTION("""COMPUTED_VALUE"""),68.27) -> 68.27 | Q23: =IFERROR(__xludf.DUMMYFUNCTION("""COMPUTED_VALUE"""),94.53) -> 94.53 | R23: =IFERROR(__xludf.DUMMYFUNCTION("""COMPUTED_VALUE"""),85.75) -> 85.75 | S23: =IFERROR(__xludf.DUMMYFUNCTION("""COMPUTED_VALUE"""),43.63) -> 43.63 | T23: =IFERROR(__xludf.DUMMYFUNCTION("""COMPUTED_VALUE"""),22.51) -> 22.51 | U23: =IFERROR(__xludf.DUMMYFUNCTION("""COMPUTED_VALUE"""),62.53) -> 62.53 | V23: =IFERROR(__xludf.DUMMYFUNCTION("""COMPUTED_VALUE"""),65.21) -> 65.21 | W23: =IFERROR(__xludf.DUMMYFUNCTION("""COMPUTED_VALUE"""),39.6) -> 39.6 | X23: =IFERROR(__xludf.DUMMYFUNCTION("""COMPUTED_VALUE"""),97.32) -> 97.32 | Y23: =IFERROR(__xludf.DUMMYFUNCTION("""COMPUTED_VALUE"""),55.87) -> 55.87 | Z23: =IFERROR(__xludf.DUMMYFUNCTION("""COMPUTED_VALUE"""),87.57) -> 87.57 | AA23: =IFERROR(__xludf.DUMMYFUNCTION("""COMPUTED_VALUE"""),47.02) -> 47.02 | AB23: =IFERROR(__xludf.DUMMYFUNCTION("""COMPUTED_VALUE"""),72.68) -> 72.68 | AC23: =IFERROR(__xludf.DUMMYFUNCTION("""COMPUTED_VALUE"""),65.54) -> 65.54 | AD23: =IFERROR(__xludf.DUMMYFUNCTION("""COMPUTED_VALUE"""),15.01) -> 15.01 | AE23: =IFERROR(__xludf.DUMMYFUNCTION("""COMPUTED_VALUE"""),24.2) -> 24.2 | AF23: =IFERROR(__xludf.DUMMYFUNCTION("""COMPUTED_VALUE"""),6.02) -> 6.02 | AG23: =IFERROR(__xludf.DUMMYFUNCTION("""COMPUTED_VALUE"""),69.24) -> 69.24
